#VRML_SIM R2022a utf8
WorldInfo {
  basicTimeStep 64
  contactProperties [
    ContactProperties {
      material2 "dumbbell"
      coulombFriction [
        0
      ]
    }
  ]
}
Viewpoint {
  orientation -0.21303938242454445 0.16979034634928986 0.962177457552793 1.833214335812937
  position 0.3213178628323544 -1.0810083776171406 0.58929167765699
}
TexturedBackground {
  texture "noon_building_overcast"
}
TexturedBackgroundLight {
  texture "noon_building_overcast"
}
Floor {
  size 1 1
}
Solid {
  translation 0 0.5 0.05
  children [
    Shape {
      appearance DEF WALL_APPEARANCE PBRAppearance {
        baseColor 0.666667 0 1
        roughness 0.5
        metalness 0
      }
      geometry DEF WALL_GEOMETRY Box {
        size 1 0.02 0.1
      }
    }
  ]
  name "wall"
  boundingObject USE WALL_GEOMETRY
}
Solid {
  translation 0 -0.5 0.05
  children [
    Shape {
      appearance DEF WALL_APPEARANCE PBRAppearance {
        baseColor 0.666667 0 1
        roughness 0.5
        metalness 0
      }
      geometry DEF WALL_GEOMETRY Box {
        size 1 0.02 0.1
      }
    }
  ]
  name "wall(1)"
  boundingObject USE WALL_GEOMETRY
}
Solid {
  translation 0.5 0 0.05
  rotation 0 0 1 1.5708
  children [
    Shape {
      appearance USE WALL_APPEARANCE
      geometry DEF WALL_GEOMETRY Box {
        size 1 0.02 0.1
      }
    }
  ]
  name "wall(2)"
  boundingObject USE WALL_GEOMETRY
}
Solid {
  translation -0.5 0 0.05
  rotation 0 0 1 1.5708
  children [
    Shape {
      appearance USE WALL_APPEARANCE
      geometry DEF WALL_GEOMETRY Box {
        size 1 0.02 0.1
      }
    }
  ]
  name "wall(3)"
  boundingObject USE WALL_GEOMETRY
}
Robot {
  translation 0 0 0.05
  children [
    DEF wheel1 HingeJoint {
      jointParameters HingeJointParameters {
        axis 0 1 0
        anchor 0.05 0.06 0
      }
      device [
        DEF wheel1 RotationalMotor {
        }
      ]
      endPoint DEF WHEEL1 Solid {
        translation 0.05 0.06 0
        rotation 1 0 0 1.5708000000000004
        children [
          DEF WHEEL Shape {
            appearance PBRAppearance {
              baseColor 0 0.666667 0
              roughness 1
              metalness 0
            }
            geometry Cylinder {
              height 0.02
              radius 0.04
            }
          }
        ]
        boundingObject USE WHEEL
        physics DEF WHEEL_PHYSICS Physics {
        }
      }
    }
    DEF wheel2 HingeJoint {
      jointParameters HingeJointParameters {
        axis 0 1 0
        anchor 0.05 -0.06 0
      }
      device [
        DEF wheel2 RotationalMotor {
        }
      ]
      endPoint DEF WHEEL2 Solid {
        translation 0.05 -0.06 0
        rotation 1 0 0 1.5708000000000004
        children [
          DEF WHEEL Shape {
            appearance PBRAppearance {
              baseColor 0 0.666667 0
              roughness 1
              metalness 0
            }
            geometry Cylinder {
              height 0.02
              radius 0.04
            }
          }
        ]
        name "solid(1)"
        boundingObject USE WHEEL
        physics DEF WHEEL_PHYSICS Physics {
        }
      }
    }
    DEF wheel3 HingeJoint {
      jointParameters HingeJointParameters {
        axis 0 1 0
        anchor -0.05 0.06 0
      }
      device [
        DEF wheel3 RotationalMotor {
        }
      ]
      endPoint DEF WHEEL3 Solid {
        translation -0.05 0.06 0
        rotation 1 0 0 1.5708000000000004
        children [
          DEF WHEEL Shape {
            appearance PBRAppearance {
              baseColor 0 0.666667 0
              roughness 1
              metalness 0
            }
            geometry Cylinder {
              height 0.02
              radius 0.04
            }
          }
        ]
        name "solid(2)"
        boundingObject USE WHEEL
        physics DEF WHEEL_PHYSICS Physics {
        }
      }
    }
    DEF wheel4 HingeJoint {
      jointParameters HingeJointParameters {
        axis 0 1 0
        anchor -0.05 -0.06 0
      }
      device [
        DEF wheel4 RotationalMotor {
        }
      ]
      endPoint DEF WHEEL4 Solid {
        translation -0.05 -0.06 0
        rotation 1 0 0 1.5708000000000004
        children [
          DEF WHEEL Shape {
            appearance PBRAppearance {
              baseColor 0 0.666667 0
              roughness 1
              metalness 0
            }
            geometry Cylinder {
              height 0.02
              radius 0.04
            }
          }
        ]
        name "solid(3)"
        boundingObject USE WHEEL
        physics DEF WHEEL_PHYSICS Physics {
        }
      }
    }
    Shape {
      appearance PBRAppearance {
        baseColor 0.666667 0 0
        roughness 1
        metalness 0
      }
      geometry DEF BOX_GEO Box {
        size 0.2 0.1 0.05
      }
    }
  ]
  name "4_wheel"
  boundingObject USE BOX_GEO
  physics Physics {
  }
}
